Workbook

Sheet Resumen
A1: Resultados de pruebas - Conexión360
A2: Generado: 2026-10-18 17:10 · Casos: Azure DevOps ingenieria-requisitos / Conexión360 (lectura por MCP) (2026-10-17) · Ejecuciones de Katalon leídas: 42
A4: Resultado | B4: Casos | C4: % del total
A5: Pasó | B5: =COUNTIF(Detalle!$H$2:$H$78,A5) | C5: =IF($B$11=0,0,B5/$B$11)
A6: Falló | B6: =COUNTIF(Detalle!$H$2:$H$78,A6) | C6: =IF($B$11=0,0,B6/$B$11)
A7: Error | B7: =COUNTIF(Detalle!$H$2:$H$78,A7) | C7: =IF($B$11=0,0,B7/$B$11)
A8: Bloqueado | B8: =COUNTIF(Detalle!$H$2:$H$78,A8) | C8: =IF($B$11=0,0,B8/$B$11)
A9: No ejecutado | B9: =COUNTIF(Detalle!$H$2:$H$78,A9) | C9: =IF($B$11=0,0,B9/$B$11)
A10: Pendiente manual | B10: =COUNTIF(Detalle!$H$2:$H$78,A10) | C10: =IF($B$11=0,0,B10/$B$11)
A11: Total | B11: =SUM(B5:B10) | C11: =IF(B11=0,0,B11/B11)
A12: Ejecutados | B12: =B5+B6+B7
A13: % de aprobación (pasó / ejecutados) | B13: =IF(B12=0,0,B5/B12)
A15: Tipo de caso | B15: Casos | C15: Pasó | D15: Falló / Error | E15: Sin ejecutar
A16: Automatizado | B16: =COUNTIF(Detalle!$E$2:$E$78,A16) | C16: =COUNTIFS(Detalle!$E$2:$E$78,A16,Detalle!$H$2:$H$78,"Pasó") | D16: =COUNTIFS(Detalle!$E$2:$E$78,A16,Detalle!$H$2:$H$78,"Falló")+COUNTIFS(Detalle!$E$2:$E$78,A16,Detalle!$H$2:$H$78,"Error") | E16: =B16-C16-D16
A17: Automatizado parcial | B17: =COUNTIF(Detalle!$E$2:$E$78,A17) | C17: =COUNTIFS(Detalle!$E$2:$E$78,A17,Detalle!$H$2:$H$78,"Pasó") | D17: =COUNTIFS(Detalle!$E$2:$E$78,A17,Detalle!$H$2:$H$78,"Falló")+COUNTIFS(Detalle!$E$2:$E$78,A17,Detalle!$H$2:$H$78,"Error") | E17: =B17-C17-D17
A18: Manual | B18: =COUNTIF(Detalle!$E$2:$E$78,A18) | C18: =COUNTIFS(Detalle!$E$2:$E$78,A18,Detalle!$H$2:$H$78,"Pasó") | D18: =COUNTIFS(Detalle!$E$2:$E$78,A18,Detalle!$H$2:$H$78,"Falló")+COUNTIFS(Detalle!$E$2:$E$78,A18,Detalle!$H$2:$H$78,"Error") | E18: =B18-C18-D18
A20: HU | B20: Historia de usuario | C20: Casos | D20: Pasó | E20: Falló / Error | F20: Sin ejecutar
A21: 3 | B21: HU1: Visualización fechas estimadas | C21: =COUNTIF(HU_Caso!$A$2:$A$113,A21) | D21: =COUNTIFS(HU_Caso!$A$2:$A$113,A21,HU_Caso!$D$2:$D$113,"Pasó") | E21: =COUNTIFS(HU_Caso!$A$2:$A$113,A21,HU_Caso!$D$2:$D$113,"Falló")+COUNTIFS(HU_Caso!$A$2:$A$113,A21,HU_Caso!$D$2:$D$113,"Error") | F21: =C21-D21-E21
A22: 28 | B22: HU1-Lista de mis envíos activos | C22: =COUNTIF(HU_Caso!$A$2:$A$113,A22) | D22: =COUNTIFS(HU_Caso!$A$2:$A$113,A22,HU_Caso!$D$2:$D$113,"Pasó") | E22: =COUNTIFS(HU_Caso!$A$2:$A$113,A22,HU_Caso!$D$2:$D$113,"Falló")+COUNTIFS(HU_Caso!$A$2:$A$113,A22,HU_Caso!$D$2:$D$113,"Error") | F22: =C22-D22-E22
A23: 29 | B23: HU2-Visualizar los envíos asignados o disponibles | C23: =COUNTIF(HU_Caso!$A$2:$A$113,A23) | D23: =COUNTIFS(HU_Caso!$A$2:$A$113,A23,HU_Caso!$D$2:$D$113,"Pasó") | E23: =COUNTIFS(HU_Caso!$A$2:$A$113,A23,HU_Caso!$D$2:$D$113,"Falló")+COUNTIFS(HU_Caso!$A$2:$A$113,A23,HU_Caso!$D$2:$D$113,"Error") | F23: =C23-D23-E23
A24: 30 | B24: HU3-Ver el detalle de un envío | C24: =COUNTIF(HU_Caso!$A$2:$A$113,A24) | D24: =COUNTIFS(HU_Caso!$A$2:$A$113,A24,HU_Caso!$D$2:$D$113,"Pasó") | E24: =COUNTIFS(HU_Caso!$A$2:$A$113,A24,HU_Caso!$D$2:$D$113,"Falló")+COUNTIFS(HU_Caso!$A$2:$A$113,A24,HU_Caso!$D$2:$D$113,"Error") | F24: =C24-D24-E24
A25: 32 | B25: HU5-Visualizar el historial del envío | C25: =COUNTIF(HU_Caso!$A$2:$A$113,A25) | D25: =COUNTIFS(HU_Caso!$A$2:$A$113,A25,HU_Caso!$D$2:$D$113,"Pasó") | E25: =COUNTIFS(HU_Caso!$A$2:$A$113,A25,HU_Caso!$D$2:$D$113,"Falló")+COUNTIFS(HU_Caso!$A$2:$A$113,A25,HU_Caso!$D$2:$D$113,"Error") | F25: =C25-D25-E25
A26: 33 | B26: HU6-Ver detalles completos del envío por medio de iconos | C26: =COUNTIF(HU_Caso!$A$2:$A$113,A26) | D26: =COUNTIFS(HU_Caso!$A$2:$A$113,A26,HU_Caso!$D$2:$D$113,"Pasó") | E26: =COUNTIFS(HU_Caso!$A$2:$A$113,A26,HU_Caso!$D$2:$D$113,"Falló")+COUNTIFS(HU_Caso!$A$2:$A$113,A26,HU_Caso!$D$2:$D$113,"Error") | F26: =C26-D26-E26
A27: 34 | B27: HU7-Buscar un envío por número de guía | C27: =COUNTIF(HU_Caso!$A$2:$A$113,A27) | D27: =COUNTIFS(HU_Caso!$A$2:$A$113,A27,HU_Caso!$D$2:$D$113,"Pasó") | E27: =COUNTIFS(HU_Caso!$A$2:$A$113,A27,HU_Caso!$D$2:$D$113,"Falló")+COUNTIFS(HU_Caso!$A$2:$A$113,A27,HU_Caso!$D$2:$D$113,"Error") | F27: =C27-D27-E27
A28: 37 | B28: HU10-Consolidar la información de los envíos en una única fuente centralizada | C28: =COUNTIF(HU_Caso!$A$2:$A$113,A28) | D28: =COUNTIFS(HU_Caso!$A$2:$A$113,A28,HU_Caso!$D$2:$D$113,"Pasó") | E28: =COUNTIFS(HU_Caso!$A$2:$A$113,A28,HU_Caso!$D$2:$D$113,"Falló")+COUNTIFS(HU_Caso!$A$2:$A$113,A28,HU_Caso!$D$2:$D$113,"Error") | F28: =C28-D28-E28
A29: 38 | B29: HU11-Consultar información centralizada de mis envíos | C29: =COUNTIF(HU_Caso!$A$2:$A$113,A29) | D29: =COUNTIFS(HU_Caso!$A$2:$A$113,A29,HU_Caso!$D$2:$D$113,"Pasó") | E29: =COUNTIFS(HU_Caso!$A$2:$A$113,A29,HU_Caso!$D$2:$D$113,"Falló")+COUNTIFS(HU_Caso!$A$2:$A$113,A29,HU_Caso!$D$2:$D$113,"Error") | F29: =C29-D29-E29
A30: 39 | B30: HU1-Actualizar automáticamente los estados de los envíos | C30: =COUNTIF(HU_Caso!$A$2:$A$113,A30) | D30: =COUNTIFS(HU_Caso!$A$2:$A$113,A30,HU_Caso!$D$2:$D$113,"Pasó") | E30: =COUNTIFS(HU_Caso!$A$2:$A$113,A30,HU_Caso!$D$2:$D$113,"Falló")+COUNTIFS(HU_Caso!$A$2:$A$113,A30,HU_Caso!$D$2:$D$113,"Error") | F30: =C30-D30-E30
A31: 40 | B31: HU2-Integrar múltiples fuentes de datos | C31: =COUNTIF(HU_Caso!$A$2:$A$113,A31) | D31: =COUNTIFS(HU_Caso!$A$2:$A$113,A31,HU_Caso!$D$2:$D$113,"Pasó") | E31: =COUNTIFS(HU_Caso!$A$2:$A$113,A31,HU_Caso!$D$2:$D$113,"Falló")+COUNTIFS(HU_Caso!$A$2:$A$113,A31,HU_Caso!$D$2:$D$113,"Error") | F31: =C31-D31-E31
A32: 41 | B32: HU1-Registrar cada cambio en los envíos | C32: =COUNTIF(HU_Caso!$A$2:$A$113,A32) | D32: =COUNTIFS(HU_Caso!$A$2:$A$113,A32,HU_Caso!$D$2:$D$113,"Pasó") | E32: =COUNTIFS(HU_Caso!$A$2:$A$113,A32,HU_Caso!$D$2:$D$113,"Falló")+COUNTIFS(HU_Caso!$A$2:$A$113,A32,HU_Caso!$D$2:$D$113,"Error") | F32: =C32-D32-E32
... A45: 214 | B45: HU6: Bloquear acceso tras 3 intentos fallidos | C45: =COUNTIF(HU_Caso!$A$2:$A$113,A45) | D45: =COUNTIFS(HU_Caso!$A$2:$A$113,A45,HU_Caso!$D$2:$D$113,"Pasó") | E45: =COUNTIFS(HU_Caso!$A$2:$A$113,A45,HU_Caso!$D$2:$D$113,"Falló")+COUNTIFS(HU_Caso!$A$2:$A$113,A45,HU_Caso!$D$2:$D$113,"Error") | F45: =C45-D45-E45
A47: Un caso enlazado a varias HU cuenta en cada una de ellas.

Sheet Hallazgos
A1: Hallazgos de la revisión
A2: Revisión estática del código (Conexion360_front, Connection360ApiCore) y de los test cases de Azure DevOps. No proviene de ejecuciones. (2026-10-17)
A4: ID | B4: Categoría | C4: Severidad | D4: Hallazgo | E4: Detalle | F4: Evidencia | G4: Casos de Azure | H4: Estado | I4: Recomendación
A5: H-01 | B5: Seguridad | C5: Crítica | D5: Un cliente puede consultar los envíos de otro cliente cambiando el idClient de la petición | E5: La API toma el idClient del query string y filtra con él. Para el rol CLIENT no lo compara con el usuario del token: el ClientAccessResolver devuelve una lista vacía sin validar y la lectura de los claims del usuario está comentada. Afecta a myshipments (allshipments, filterShipments, allhistory, filterhistory, detailsshipments), home (totals, filters) y reports/home. El API Gateway no reescribe el parámetro. | F5: Connection360.Api/Controllers/MyShipmentsController.cs:44-57; Connection360.Application/UseCases/GetMyShipmentsUseCase.cs:43-50; Connection360.Application/Services/ClientAccessResolver.cs:26-27; Connection360.Api/Controllers/HomeController.cs:105-111 (comentado); Connection360.ApiGateway/appsettings.json (ReverseProxy: solo agrega X-Forwarded-By) | G5: 318, 357, 365 | H5: Detectado en el código. Se espera que 318 y 365 FALLEN al ejecutarlos. | I5: Tomar el documento del cliente desde el token (claim) en el backend y rechazar (403) cualquier idClient distinto.
A6: H-02 | B6: Seguridad | C6: Alta | D6: Un analista puede ver los clientes asignados a otro colaborador | E6: Para ANALISTAOPE y ANALISTASAC, los clientes permitidos se buscan con el idClient recibido en la URL (GetCustomersByCollaboratorAsync(request.IdClient)). Si el analista envía el documento de otro colaborador, obtiene los clientes de ese colaborador. | F6: Connection360.Application/Services/ClientAccessResolver.cs:26-46 | G6: 359 | H6: Detectado en el código. El TC359 solo valida la interfaz y no lo detecta; falta un caso de API. | I6: Igual que H-01: identificar al colaborador por el token. Agregar en Azure un caso de API para analistas.
A7: H-03 | B7: Seguridad | C7: Crítica | D7: Cuatro servicios sin autenticación permiten crear datos | E7: GET /settings/createcustomerdb, GET /settings/createcollaboratordb, GET /settings/createcustomercollaboratordb y POST /settings/generatenotificationOutboxTest están marcados con [AllowAnonymous]. Los tres GET crean registros en la base de datos, y el POST genera eventos de notificación. | F7: Connection360.Api/Controllers/SettingsController.cs:276-325 | G7: 378 | H7: Detectado en el código. El TC378 FALLARÁ y, al ejecutarlo, creará los NIT de prueba 999000111 y 999000112: no correrlo en el ambiente compartido hasta corregir. | I7: Quitar [AllowAnonymous] (o retirar los servicios de prueba del despliegue) y no crear datos con métodos GET.
A8: H-04 | B8: Seguridad | C8: Crítica | D8: Un servicio sin autenticación devuelve todas las notificaciones de todos los clientes | E8: GET /notifications/allnotificationslistTest está marcado con [AllowAnonymous] y devuelve la lista completa de notificaciones almacenadas, sin filtrar por cliente. | F8: Connection360Notification.Api/Controllers/NotificationsController.cs:91-99 | G8: 378, 367 | H8: Detectado en el código. | I8: Eliminar el servicio de prueba o exigir autenticación y filtrar por cliente.
A9: H-05 | B9: Seguridad | C9: Media | D9: El API Gateway tiene credenciales escritas en el código y emite tokens con el mismo emisor que Auth0 | E9: TokenEndpoints define tres clientes (admin-client, editor-client, reader-client) con sus secretos en el código y firma tokens con el mismo Issuer y Audience que usa Auth0. La API valida la firma con las llaves de Auth0 (Authority), así que lo más probable es que rechace esos tokens, pero hay que confirmarlo. | F9: Connection360.ApiGateway/Endpoints/TokenEndpoints.cs:42-55; Connection360.ApiGateway/appsettings.json:10-11; Connection360.Api/Extensions/ServiceCollectionExtensions.cs:120-130 | G9: 384 | H9: Por confirmar con el TC384 (manual). | I9: Sacar los secretos del código (User Secrets o Key Vault) y usar un emisor propio para los tokens del Gateway.
A10: H-06 | B10: Funcional | C10: Media | D10: El ranking de clientes de Reportes muestra datos simulados | E10: GET /reports/home todavía no devuelve topClients, así que el front completa la tarjeta "Top clientes por cantidad de envíos" con datos simulados (mockTopClients). El ADMIN ve un ranking que no es real. | F10: Conexion360_front/src/app/core/services/api-reports.service.ts:34-49; Conexion360_front/src/app/mocks/data/mock-top-clients.ts | G10: 374 | H10: Detectado en el código. La parte del ADMIN del TC374 pasaría, pero con datos simulados. | I10: Implementar topClients en /reports/home (filtrado por rol) y retirar el mock.
A11: H-07 | B11: Casos de prueba | C11: Media | D11: Resultados esperados en Azure que no coinciden con la aplicación | E11: 322: el buscador no es obligatorio; con el campo vacío se listan todos los envíos. 306 y 323: el mensaje real es "Ningún envío coincide con la búsqueda o los filtros seleccionados.". 304-306: no hay botón Buscar; la búsqueda es automática. 320: no existe una vista global separada. 340: el Dashboard no tiene totales por estado. | F11: Conexion360_front: core/utils/input-rules.ts (searchQuery.required = false); features/shipments/shipment-list/shipment-list.ts:262-268; features/dashboard/dashboard.ts:183-222 | G11: 304, 305, 306, 320, 322, 323, 340 | H11: Los scripts de Katalon ya están ajustados al comportamiento real; falta actualizar los casos en Azure. | I11: Actualizar pasos y resultados esperados de esos casos en Azure DevOps.
A12: H-08 | B12: Trazabilidad | C12: Baja | D12: Enlaces invertidos y títulos repetidos en Azure | E12: La HU 35 está enlazada como "Tests" al caso 304. Las HU 338 y 339 (creadas como contenedores) usan "Tests" hacia 14 casos, en sentido invertido. Hay títulos repetidos entre HU distintas (por ejemplo, "Test HU2-1" en 309, 335, 341, 347 y 351). | F12: Consultas WIQL de vínculos User Story - Test Case (Azure DevOps, 2026-10-17) | G12: 304, 340, 341, 344, 348, 349, 352, 369, 382, 329, 330, 331, 332, 333, 335 | H12: Confirmado en Azure. | I12: Revisar con Iván si las HU contenedor son intencionales. Corregir el enlace del 304 y numerar los títulos con el ID de la HU.
A13: H-09 | B13: Cobertura | C13: Media | D13: HU cerradas sin test cases | E13: No tienen ningún caso enlazado con Tested By: 7 (Registro Plataforma), 31 (Ubicación en mapa), 35 (Búsqueda por múltiples criterios; solo tiene el enlace invertido al 304), 123 (Recuperación de contraseña) y 213 (Integridad de datos). | F13: BackLog.xlsx y vínculos de Azure DevOps (2026-10-17) | H13: Confirmado en Azure. | I13: Crear al menos un caso por HU cerrada.
A14: H-10 | B14: Ambiente | C14: Alta | D14: La API devolvió 503 durante toda la ejecución del 18-oct y faltan usuarios de prueba | E14: El 2026-10-18 se ejecutaron los casos automatizados contra https://conexion360.space. La API (https://c360-api.edisonestival.workers.dev/api/v1) respondió 503 a todas las peticiones, incluso sin token, así que el proxy de Cloudflare no alcanza el backend. Las listas, el detalle y el Dashboard quedaron vacíos. Además, siguen en COMPLETAR los usuarios cliente sin envíos (C), Cliente D, ADMIN, analista y usuario sin rol. Las guías de prueba (HBLQA0001, HBLQA0003, HBLQA0004) son del NIT 900111222 y no del cliente usado, 3127584817. | F14: Reports/20261018_163618 (P1), Reports/20261018_165316 (Lote2), Reports/20261018_170614 (TS_Reejecucion). TC373 y TC351: 'responde 503 (esperado 401/403)'. | G14: 304, 307, 308, 316, 318, 319, 321, 324, 325, 340, 341, 344, 349, 350, 351, 353, 356, 358, 359, 373, 374 | H14: Bloqueante. Casi todos los fallos de esta ejecución son del ambiente y no de la aplicación. | I14: Levantar el backend detrás del Worker, completar los usuarios del Profile y cargar guías del cliente 3127584817 (o usar un cliente del NIT 900111222). Luego repetir P1, Lote2 y TS_Reejecucion.
A15: H-11 | B15: Casos de prueba | C15: Alta | D15: Casos que salieron Pasó el 18-oct sin haber probado nada (falsos positivos) | E15: 357 y 365 verifican solo que la respuesta no contenga guías del Cliente B; la página de error del 503 tampoco las contiene, y en 365 los /home/totals propio y ajeno son el mismo 503. 317 acepta 'No se pudo cargar el detalle', que aparece por el 503. 313 usó el Cliente D con correo COMPLETAR, así que no bloqueó ninguna cuenta real. Estos resultados no son válidos. | F15: Scripts de TC357, TC365, TC317 y TC313; TS_Reejecucion 20261018_170614 y TS_P1_RutaCritica 20261018_163618. | G15: 313, 317, 357, 365 | H15: Resultados inválidos; repetir con el ambiente arriba. | I15: Agregar a 357 y 365 un paso de control como el de 318 (la consulta propia debe responder 200 con datos) antes de evaluar la consulta ajena. En 317, exigir 'Envío no encontrado' y no aceptar el error de carga.
A16: H-12 | B16: Automatización | C16: Media | D16: Dos defectos del keyword Helpers, corregidos el 18-oct | E16: (1) llamarApiCon usaba WebUI.executeAsyncJavaScript, que no existe en Katalon: todos los casos con llamadas a la API terminaban en Error. Ahora usa JavascriptExecutor.executeAsyncScript de Selenium. (2) css() y xpath() usaban el selector como id del TestObject; el self-healing lo usa como ruta de archivo y fallaba con las comillas (TC324). Ahora el id es un hash del selector. | F16: Keywords/conexion360/Helpers.groovy; errores MissingMethodException e InvalidPathException en Reports/20261018_163618 y 20261018_165316. | G16: 318, 324, 351, 357, 365, 373 | H16: Corregido. Los 6 casos se repitieron en TS_Reejecucion y ahora fallan o pasan por el ambiente, no por el script. | I16: Ninguna adicional.

Sheet Detalle
A1: ID Azure | B1: Título | C1: HU | D1: Responsable | E1: Tipo | F1: Suite | G1: Caso Katalon | H1: Resultado | I1: Duración (s) | J1: Fecha ejecución | K1: Fuente del resultado | L1: Mensaje / observación | M1: Nota | N1: Hallazgos
A2: 304 | B2: Test HU7-1- Verificar que se obtenga la información asociada a una guía | C2: 34 - HU7-Buscar un envío por número de guía | D2: Yesid Alexander García López | E2: Automatizado | F2: TS_P1_RutaCritica | G2: Test Cases/P1/HU34_BusquedaGuia/TC304_BusquedaGuiaExistente | H2: Falló | I2: 47.2 | J2: 2026-10-18 21:36:55 | K2: Katalon (TS_P1_RutaCritica) | L2: Test Cases/P1/HU34_BusquedaGuia/TC304_BusquedaGuiaExistente FAILED. Reason: com.kms.katalon.core.exception.StepFailedException: No se cumple: La guía aparece en los resultados at com.kms.katalon.core.util.KeywordUtil.markFailedAndStop(KeywordUtil.java:31) at conexion360.Helpers.verificar(Helpers.groovy:312) at TC304_BusquedaGuiaExistente.run(TC304_BusquedaGuiaExistente:23) at com.kms.katalon.core.main.ScriptEngine.run(ScriptEngine.java:203) at com.kms.katalon.core.main.ScriptEngine.runScriptAsRawText(ScriptEngine.java:115) at com.kms.katalon.core.main.TestCaseExecutor.runScript(TestCaseExecutor.java:533) at com.kms.katalon.core.main.TestCaseExecutor.doExecute(TestCaseExecutor.java:524) at com.kms.katalon.core.main.TestCaseExecutor.processExecutionPhase(TestCaseExecutor.java:503) at com.kms.katalon.core.main.TestCaseExecutor.accessMainPhase(TestCaseExecutor.java:495) at com.kms.katalon.core.main.TestCaseExecutor.execute(TestCaseExecutor.java:359) at com.kms.katalon.core.commo | N2: H-07, H-08, H-10
A3: 305 | B3: Test HU7-2 - Verificar que no se permita la búsqueda con caracteres especiales diferentes de guion | C3: 34 - HU7-Buscar un envío por número de guía | D3: Yesid Alexander García López | E3: Automatizado | F3: TS_P1_RutaCritica | G3: Test Cases/P1/HU34_BusquedaGuia/TC305_BusquedaCaracteresEspeciales | H3: Pasó | I3: 17.1 | J3: 2026-10-18 21:36:55 | K3: Katalon (TS_P1_RutaCritica) | N3: H-07
A4: 306 | B4: Test HU7-3 - Verificar búsqueda de guía sin resultados asociados | C4: 34 - HU7-Buscar un envío por número de guía | D4: Yesid Alexander García López | E4: Automatizado | F4: TS_P1_RutaCritica | G4: Test Cases/P1/HU34_BusquedaGuia/TC306_BusquedaGuiaInexistente | H4: Falló | I4: 30.9 | J4: 2026-10-18 21:36:55 | K4: Katalon (TS_P1_RutaCritica) | L4: Test Cases/P1/HU34_BusquedaGuia/TC306_BusquedaGuiaInexistente FAILED. Reason: com.kms.katalon.core.exception.StepFailedException: No apareció el texto: Ningún envío coincide con la búsqueda o los filtros seleccionados. at com.kms.katalon.core.util.KeywordUtil.markFailedAndStop(KeywordUtil.java:31) at conexion360.Helpers.esperarTexto(Helpers.groovy:107) at conexion360.Helpers.esperarTexto(Helpers.groovy) at TC306_BusquedaGuiaInexistente.run(TC306_BusquedaGuiaInexistente:24) at com.kms.katalon.core.main.ScriptEngine.run(ScriptEngine.java:203) at com.kms.katalon.core.main.ScriptEngine.runScriptAsRawText(ScriptEngine.java:115) at com.kms.katalon.core.main.TestCaseExecutor.runScript(TestCaseExecutor.java:533) at com.kms.katalon.core.main.TestCaseExecutor.doExecute(TestCaseExecutor.java:524) at com.kms.katalon.core.main.TestCaseExecutor.processExecutionPhase(TestCaseExecutor.java:503) at com.kms.katalon.core.main.TestCaseExecutor.accessMainPhase(TestCaseExecutor.java:495) at com.k | N4: H-07
A5: 307 | B5: Test HU1-1 Verificar que se listen mis envios | C5: 28 - HU1-Lista de mis envíos activos | D5: Eider Santiago Sánchez Lopera | E5: Automatizado | F5: TS_P1_RutaCritica | G5: Test Cases/P1/HU28_MisEnviosActivos/TC307_ListarMisEnvios | H5: Falló | I5: 44 | J5: 2026-10-18 21:36:55 | K5: Katalon (TS_P1_RutaCritica) | L5: Test Cases/P1/HU28_MisEnviosActivos/TC307_ListarMisEnvios FAILED. Reason: com.kms.katalon.core.exception.StepFailedException: No se cumple: Se listan envíos (0 en la primera página) at com.kms.katalon.core.util.KeywordUtil.markFailedAndStop(KeywordUtil.java:31) at conexion360.Helpers.verificar(Helpers.groovy:312) at TC307_ListarMisEnvios.run(TC307_ListarMisEnvios:23) at com.kms.katalon.core.main.ScriptEngine.run(ScriptEngine.java:203) at com.kms.katalon.core.main.ScriptEngine.runScriptAsRawText(ScriptEngine.java:115) at com.kms.katalon.core.main.TestCaseExecutor.runScript(TestCaseExecutor.java:533) at com.kms.katalon.core.main.TestCaseExecutor.doExecute(TestCaseExecutor.java:524) at com.kms.katalon.core.main.TestCaseExecutor.processExecutionPhase(TestCaseExecutor.java:503) at com.kms.katalon.core.main.TestCaseExecutor.accessMainPhase(TestCaseExecutor.java:495) at com.kms.katalon.core.main.TestCaseExecutor.execute(TestCaseExecutor.java:359) at com.kms.katalon.core.common.Comm | N5: H-10
A6: 308 | B6: Test HU1-2 Verificar el filtro por estado para mis envíos | C6: 28 - HU1-Lista de mis envíos activos | D6: Eider Santiago Sánchez Lopera | E6: Automatizado | F6: TS_P1_RutaCritica | G6: Test Cases/P1/HU28_MisEnviosActivos/TC308_FiltroPorEstado | H6: Falló | I6: 63.1 | J6: 2026-10-18 21:36:55 | K6: Katalon (TS_P1_RutaCritica) | L6: Test Cases/P1/HU28_MisEnviosActivos/TC308_FiltroPorEstado FAILED. Reason: com.kms.katalon.core.exception.StepFailedException: No apareció el texto: Ningún envío coincide con la búsqueda o los filtros seleccionados. at com.kms.katalon.core.util.KeywordUtil.markFailedAndStop(KeywordUtil.java:31) at conexion360.Helpers.esperarTexto(Helpers.groovy:107) at conexion360.Helpers.esperarTexto(Helpers.groovy) at TC308_FiltroPorEstado.run(TC308_FiltroPorEstado:28) at com.kms.katalon.core.main.ScriptEngine.run(ScriptEngine.java:203) at com.kms.katalon.core.main.ScriptEngine.runScriptAsRawText(ScriptEngine.java:115) at com.kms.katalon.core.main.TestCaseExecutor.runScript(TestCaseExecutor.java:533) at com.kms.katalon.core.main.TestCaseExecutor.doExecute(TestCaseExecutor.java:524) at com.kms.katalon.core.main.TestCaseExecutor.processExecutionPhase(TestCaseExecutor.java:503) at com.kms.katalon.core.main.TestCaseExecutor.accessMainPhase(TestCaseExecutor.java:495) at com.kms.katalon.core.main | N6: H-10
A7: 309 | B7: Test HU2-1 - Verificar inicio de sesión exitoso con credenciales válidas | C7: 121 - HU2: Inicio de sesión | D7: Eider Santiago Sánchez Lopera | E7: Automatizado | F7: TS_P1_RutaCritica | G7: Test Cases/P1/HU121_InicioSesion/TC309_LoginExitoso | H7: Pasó | I7: 12.5 | J7: 2026-10-18 21:36:55 | K7: Katalon (TS_P1_RutaCritica)
A8: 310 | B8: Test HU2-2 - Verificar que no se permita el inicio de sesión con contraseña incorrecta | C8: 121 - HU2: Inicio de sesión | D8: Eider Santiago Sánchez Lopera | E8: Automatizado | F8: TS_P1_RutaCritica | G8: Test Cases/P1/HU121_InicioSesion/TC310_LoginContrasenaIncorrecta | H8: Pasó | I8: 17.1 | J8: 2026-10-18 21:36:55 | K8: Katalon (TS_P1_RutaCritica)
A9: 311 | B9: Test HU2-3 - Verificar inicio de sesión con un correo no registrado | C9: 121 - HU2: Inicio de sesión | D9: Eider Santiago Sánchez Lopera | E9: Automatizado | F9: TS_P1_RutaCritica | G9: Test Cases/P1/HU121_InicioSesion/TC311_LoginCorreoNoRegistrado | H9: Pasó | I9: 11.2 | J9: 2026-10-18 21:36:55 | K9: Katalon (TS_P1_RutaCritica)
A10: 312 | B10: Test HU2-4 - Verificar que una ruta protegida redirija al inicio de sesión sin sesión activa | C10: 121 - HU2: Inicio de sesión | D10: Eider Santiago Sánchez Lopera | E10: Automatizado | F10: TS_P1_RutaCritica | G10: Test Cases/P1/HU121_InicioSesion/TC312_RutaProtegidaSinSesion | H10: Pasó | I10: 4.3 | J10: 2026-10-18 21:36:55 | K10: Katalon (TS_P1_RutaCritica)
A11: 313 | B11: Test HU6-1 - Verificar bloqueo de la cuenta al tercer intento fallido | C11: 214 - HU6: Bloquear acceso tras 3 intentos fallidos | D11: Eider Santiago Sánchez Lopera | E11: Automatizado | F11: TS_P1_RutaCritica | G11: Test Cases/P1/HU214_BloqueoIntentos/TC313_BloqueoTercerIntento | H11: Pasó | I11: 27.1 | J11: 2026-10-18 21:36:55 | K11: Katalon (TS_P1_RutaCritica) | N11: H-11
A12: 314 | B12: Test HU6-2 - Verificar que 2 intentos fallidos no bloqueen la cuenta | C12: 214 - HU6: Bloquear acceso tras 3 intentos fallidos | D12: Eider Santiago Sánchez Lopera | E12: Automatizado | F12: TS_P1_RutaCritica | G12: Test Cases/P1/HU214_BloqueoIntentos/TC314_DosIntentosNoBloquean | H12: Falló | I12: 52.2 | J12: 2026-10-18 21:36:55 | K12: Katalon (TS_P1_RutaCritica) | L12: Test Cases/P1/HU214_BloqueoIntentos/TC314_DosIntentosNoBloquean FAILED. Reason: com.kms.katalon.core.exception.StepFailedException: No se cumple: La app redirige a /dashboard at com.kms.katalon.core.util.KeywordUtil.markFailedAndStop(KeywordUtil.java:31) at conexion360.Helpers.verificar(Helpers.groovy:312) at TC314_DosIntentosNoBloquean.run(TC314_DosIntentosNoBloquean:28) at com.kms.katalon.core.main.ScriptEngine.run(ScriptEngine.java:203) at com.kms.katalon.core.main.ScriptEngine.runScriptAsRawText(ScriptEngine.java:115) at com.kms.katalon.core.main.TestCaseExecutor.runScript(TestCaseExecutor.java:533) at com.kms.katalon.core.main.TestCaseExecutor.doExecute(TestCaseExecutor.java:524) at com.kms.katalon.core.main.TestCaseExecutor.processExecutionPhase(TestCaseExecutor.java:503) at com.kms.katalon.core.main.TestCaseExecutor.accessMainPhase(TestCaseExecutor.java:495) at com.kms.katalon.core.main.TestCaseExecutor.execute(TestCaseExecutor.java:359) at com.kms.katalon.core.common
A13: 315 | B13: Test HU6-3 - Verificar desbloqueo de la cuenta mediante el correo de Auth0 | C13: 214 - HU6: Bloquear acceso tras 3 intentos fallidos | D13: Eider Santiago Sánchez Lopera | E13: Manual | H13: Pendiente manual | M13: Requiere abrir el correo de desbloqueo de Auth0
A14: 316 | B14: Test HU3-1 - Verificar que el cliente solo visualice sus propios envíos | C14: 126 - HU3: Visualización envios | D14: Eider Santiago Sánchez Lopera | E14: Automatizado | F14: TS_P1_RutaCritica | G14: Test Cases/P1/HU126_OwnershipEnvios/TC316_ClienteSoloVeSusEnvios | H14: Falló | I14: 47.9 | J14: 2026-10-18 21:36:55 | K14: Katalon (TS_P1_RutaCritica) | L14: Test Cases/P1/HU126_OwnershipEnvios/TC316_ClienteSoloVeSusEnvios FAILED. Reason: com.kms.katalon.core.exception.StepFailedException: No se cumple: Aparece la guía propia at com.kms.katalon.core.util.KeywordUtil.markFailedAndStop(KeywordUtil.java:31) at conexion360.Helpers.verificar(Helpers.groovy:312) at TC316_ClienteSoloVeSusEnvios.run(TC316_ClienteSoloVeSusEnvios:24) at com.kms.katalon.core.main.ScriptEngine.run(ScriptEngine.java:203) at com.kms.katalon.core.main.ScriptEngine.runScriptAsRawText(ScriptEngine.java:115) at com.kms.katalon.core.main.TestCaseExecutor.runScript(TestCaseExecutor.java:533) at com.kms.katalon.core.main.TestCaseExecutor.doExecute(TestCaseExecutor.java:524) at com.kms.katalon.core.main.TestCaseExecutor.processExecutionPhase(TestCaseExecutor.java:503) at com.kms.katalon.core.main.TestCaseExecutor.accessMainPhase(TestCaseExecutor.java:495) at com.kms.katalon.core.main.TestCaseExecutor.execute(TestCaseExecutor.java:359) at com.kms.katalon.core.common.Co | N14: H-10
A15: 317 | B15: Test HU3-2 - Verificar que el cliente no pueda abrir el detalle de un envío ajeno por URL | C15: 126 - HU3: Visualización envios | D15: Eider Santiago Sánchez Lopera | E15: Automatizado | F15: TS_P1_RutaCritica | G15: Test Cases/P1/HU126_OwnershipEnvios/TC317_DetalleAjenoPorUrl | H15: Pasó | I15: 22 | J15: 2026-10-18 21:36:55 | K15: Katalon (TS_P1_RutaCritica) | N15: H-11
A16: 318 | B16: Test HU3-3 - Verificar que la API rechace la consulta de un envío ajeno | C16: 126 - HU3: Visualización envios | D16: Eider Santiago Sánchez Lopera | E16: Automatizado | F16: TS_P1_RutaCritica | G16: Test Cases/P1/HU126_OwnershipEnvios/TC318_ApiRechazaEnvioAjeno | H16: Falló | I16: 19.7 | J16: 2026-10-18 22:06:24 | K16: Katalon (TS_Reejecucion) | L16: Test Cases/P1/HU126_OwnershipEnvios/TC318_ApiRechazaEnvioAjeno FAILED. Reason: com.kms.katalon.core.exception.StepFailedException: No se cumple: El token y el endpoint funcionan con el envío propio at com.kms.katalon.core.util.KeywordUtil.markFailedAndStop(KeywordUtil.java:31) at conexion360.Helpers.verificar(Helpers.groovy:323) at TC318_ApiRechazaEnvioAjeno.run(TC318_ApiRechazaEnvioAjeno:24) at com.kms.katalon.core.main.ScriptEngine.run(ScriptEngine.java:203) at com.kms.katalon.core.main.ScriptEngine.runScriptAsRawText(ScriptEngine.java:115) at com.kms.katalon.core.main.TestCaseExecutor.runScript(TestCaseExecutor.java:533) at com.kms.katalon.core.main.TestCaseExecutor.doExecute(TestCaseExecutor.java:524) at com.kms.katalon.core.main.TestCaseExecutor.processExecutionPhase(TestCaseExecutor.java:503) at com.kms.katalon.core.main.TestCaseExecutor.accessMainPhase(TestCaseExecutor.java:495) at com.kms.katalon.core.main.TestCaseExecutor.execute(TestCaseExecutor.java:359) at com.km | N16: H-01, H-10, H-12
A17: 319 | B17: Test HU4-1 - Verificar que el empleado visualice los envíos de todos los clientes | C17: 127 - HU4: Acceso envios clientes | D17: Eider Santiago Sánchez Lopera | E17: Automatizado | F17: TS_P1_RutaCritica | G17: Test Cases/P1/HU127_AccesoPorRol/TC319_AdminVeTodosLosEnvios | H17: Falló | I17: 102.1 | J17: 2026-10-18 21:36:55 | K17: Katalon (TS_P1_RutaCritica) | L17: Test Cases/P1/HU127_AccesoPorRol/TC319_AdminVeTodosLosEnvios FAILED. Reason: com.kms.katalon.core.exception.StepFailedException: No se cumple: La vista interna muestra la columna "Cliente" at com.kms.katalon.core.util.KeywordUtil.markFailedAndStop(KeywordUtil.java:31) at conexion360.Helpers.verificar(Helpers.groovy:312) at TC319_AdminVeTodosLosEnvios.run(TC319_AdminVeTodosLosEnvios:22) at com.kms.katalon.core.main.ScriptEngine.run(ScriptEngine.java:203) at com.kms.katalon.core.main.ScriptEngine.runScriptAsRawText(ScriptEngine.java:115) at com.kms.katalon.core.main.TestCaseExecutor.runScript(TestCaseExecutor.java:533) at com.kms.katalon.core.main.TestCaseExecutor.doExecute(TestCaseExecutor.java:524) at com.kms.katalon.core.main.TestCaseExecutor.processExecutionPhase(TestCaseExecutor.java:503) at com.kms.katalon.core.main.TestCaseExecutor.accessMainPhase(TestCaseExecutor.java:495) at com.kms.katalon.core.main.TestCaseExecutor.execute(TestCaseExecutor.java:359) at com.kms.katal | N17: H-10
A18: 320 | B18: Test HU4-2 - Verificar que un cliente no acceda a la vista global de envíos | C18: 127 - HU4: Acceso envios clientes | D18: Eider Santiago Sánchez Lopera | E18: Automatizado | F18: TS_P1_RutaCritica | G18: Test Cases/P1/HU127_AccesoPorRol/TC320_ClienteSinVistaGlobal | H18: Pasó | I18: 46.9 | J18: 2026-10-18 21:36:55 | K18: Katalon (TS_P1_RutaCritica) | N18: H-07
A19: 321 | B19: Test HU1-3 - Verificar mensaje cuando el cliente no tiene envíos activos | C19: 28 - HU1-Lista de mis envíos activos | D19: Eider Santiago Sánchez Lopera | E19: Automatizado | F19: TS_P1_RutaCritica | G19: Test Cases/P1/HU28_MisEnviosActivos/TC321_SinEnviosActivos | H19: Falló | I19: 103.1 | J19: 2026-10-18 21:36:55 | K19: Katalon (TS_P1_RutaCritica) | L19: Test Cases/P1/HU28_MisEnviosActivos/TC321_SinEnviosActivos FAILED. Reason: com.kms.katalon.core.exception.StepFailedException: No apareció el texto: Aún no tienes envíos asociados at com.kms.katalon.core.util.KeywordUtil.markFailedAndStop(KeywordUtil.java:31) at conexion360.Helpers.esperarTexto(Helpers.groovy:107) at TC321_SinEnviosActivos.run(TC321_SinEnviosActivos:21) at com.kms.katalon.core.main.ScriptEngine.run(ScriptEngine.java:203) at com.kms.katalon.core.main.ScriptEngine.runScriptAsRawText(ScriptEngine.java:115) at com.kms.katalon.core.main.TestCaseExecutor.runScript(TestCaseExecutor.java:533) at com.kms.katalon.core.main.TestCaseExecutor.doExecute(TestCaseExecutor.java:524) at com.kms.katalon.core.main.TestCaseExecutor.processExecutionPhase(TestCaseExecutor.java:503) at com.kms.katalon.core.main.TestCaseExecutor.accessMainPhase(TestCaseExecutor.java:495) at com.kms.katalon.core.main.TestCaseExecutor.execute(TestCaseExecutor.java:359) at com.kms.katalon.core.common.C | N19: H-10
A20: 322 | B20: Test HU7-4 - Verificar búsqueda con el campo de guía vacío | C20: 34 - HU7-Buscar un envío por número de guía | D20: Eider Santiago Sánchez Lopera | E20: Automatizado | F20: TS_P1_RutaCritica | G20: Test Cases/P1/HU34_BusquedaGuia/TC322_BusquedaCampoVacio | H20: Falló | I20: 23.9 | J20: 2026-10-18 21:36:55 | K20: Katalon (TS_P1_RutaCritica) | L20: Test Cases/P1/HU34_BusquedaGuia/TC322_BusquedaCampoVacio FAILED. Reason: com.kms.katalon.core.exception.StepFailedException: No se cumple: La búsqueda se limpia at com.kms.katalon.core.util.KeywordUtil.markFailedAndStop(KeywordUtil.java:31) at conexion360.Helpers.verificar(Helpers.groovy:312) at TC322_BusquedaCampoVacio.run(TC322_BusquedaCampoVacio:29) at com.kms.katalon.core.main.ScriptEngine.run(ScriptEngine.java:203) at com.kms.katalon.core.main.ScriptEngine.runScriptAsRawText(ScriptEngine.java:115) at com.kms.katalon.core.main.TestCaseExecutor.runScript(TestCaseExecutor.java:533) at com.kms.katalon.core.main.TestCaseExecutor.doExecute(TestCaseExecutor.java:524) at com.kms.katalon.core.main.TestCaseExecutor.processExecutionPhase(TestCaseExecutor.java:503) at com.kms.katalon.core.main.TestCaseExecutor.accessMainPhase(TestCaseExecutor.java:495) at com.kms.katalon.core.main.TestCaseExecutor.execute(TestCaseExecutor.java:359) at com.kms.katalon.core.common.CommonExecutor.acce | N20: H-07
A21: 323 | B21: Test HU7-5 - Verificar que el cliente no obtenga datos al buscar una guía de otro cliente | C21: 34 - HU7-Buscar un envío por número de guía | D21: Eider Santiago Sánchez Lopera | E21: Automatizado | F21: TS_P1_RutaCritica | G21: Test Cases/P1/HU34_BusquedaGuia/TC323_BusquedaGuiaOtroCliente | H21: Falló | I21: 33 | J21: 2026-10-18 21:36:55 | K21: Katalon (TS_P1_RutaCritica) | L21: Test Cases/P1/HU34_BusquedaGuia/TC323_BusquedaGuiaOtroCliente FAILED. Reason: com.kms.katalon.core.exception.StepFailedException: No apareció el texto: Ningún envío coincide con la búsqueda o los filtros seleccionados. at com.kms.katalon.core.util.KeywordUtil.markFailedAndStop(KeywordUtil.java:31) at conexion360.Helpers.esperarTexto(Helpers.groovy:107) at conexion360.Helpers.esperarTexto(Helpers.groovy) at TC323_BusquedaGuiaOtroCliente.run(TC323_BusquedaGuiaOtroCliente:23) at com.kms.katalon.core.main.ScriptEngine.run(ScriptEngine.java:203) at com.kms.katalon.core.main.ScriptEngine.runScriptAsRawText(ScriptEngine.java:115) at com.kms.katalon.core.main.TestCaseExecutor.runScript(TestCaseExecutor.java:533) at com.kms.katalon.core.main.TestCaseExecutor.doExecute(TestCaseExecutor.java:524) at com.kms.katalon.core.main.TestCaseExecutor.processExecutionPhase(TestCaseExecutor.java:503) at com.kms.katalon.core.main.TestCaseExecutor.accessMainPhase(TestCaseExecutor.java:495) at com.k | N21: H-07
A22: 324 | B22: Test HU3-1 - Verificar que se muestre el detalle completo de un envío propio | C22: 30 - HU3-Ver el detalle de un envío | D22: Eider Santiago Sánchez Lopera | E22: Automatizado | F22: TS_P1_RutaCritica | G22: Test Cases/P1/HU30_DetalleEnvio/TC324_DetalleEnvioPropio | H22: Falló | I22: 31.8 | J22: 2026-10-18 22:06:24 | K22: Katalon (TS_Reejecucion) | L22: Test Cases/P1/HU30_DetalleEnvio/TC324_DetalleEnvioPropio FAILED. Reason: com.kms.katalon.core.exception.StepFailedException: Unable to click on object 'css_2950d483' at com.kms.katalon.core.webui.keyword.internal.WebUIKeywordMain.stepFailed(WebUIKeywordMain.groovy:177) at com.kms.katalon.core.webui.keyword.internal.WebUIKeywordMain.runKeyword(WebUIKeywordMain.groovy:49) at com.kms.katalon.core.webui.keyword.internal.WebUIKeywordMain.runKeywordUntilTimeout(WebUIKeywordMain.groovy:133) at com.kms.katalon.core.webui.keyword.builtin.ClickKeyword.click(ClickKeyword.groovy:72) at com.kms.katalon.core.webui.keyword.builtin.ClickKeyword.execute(ClickKeyword.groovy:38) at com.kms.katalon.core.keyword.internal.KeywordExecutor.executeKeywordForPlatform(KeywordExecutor.groovy:106) at com.kms.katalon.core.webui.keyword.WebUiBuiltInKeywords.click(WebUiBuiltInKeywords.groovy:722) at TC324_DetalleEnvioPropio.run(TC324_DetalleEnvioPropio:20) at com.kms.katalon.core.main.ScriptEngine.run(Script | N22: H-10, H-12
A23: 325 | B23: Test HU3-2 - Verificar el detalle de un envío inexistente | C23: 30 - HU3-Ver el detalle de un envío | D23: Eider Santiago Sánchez Lopera | E23: Automatizado | F23: TS_P1_RutaCritica | G23: Test Cases/P1/HU30_DetalleEnvio/TC325_DetalleEnvioInexistente | H23: Falló | I23: 42.5 | J23: 2026-10-18 21:36:55 | K23: Katalon (TS_P1_RutaCritica) | L23: Test Cases/P1/HU30_DetalleEnvio/TC325_DetalleEnvioInexistente FAILED. Reason: com.kms.katalon.core.exception.StepFailedException: No apareció el texto: Envío no encontrado at com.kms.katalon.core.util.KeywordUtil.markFailedAndStop(KeywordUtil.java:31) at conexion360.Helpers.esperarTexto(Helpers.groovy:107) at TC325_DetalleEnvioInexistente.run(TC325_DetalleEnvioInexistente:21) at com.kms.katalon.core.main.ScriptEngine.run(ScriptEngine.java:203) at com.kms.katalon.core.main.ScriptEngine.runScriptAsRawText(ScriptEngine.java:115) at com.kms.katalon.core.main.TestCaseExecutor.runScript(TestCaseExecutor.java:533) at com.kms.katalon.core.main.TestCaseExecutor.doExecute(TestCaseExecutor.java:524) at com.kms.katalon.core.main.TestCaseExecutor.processExecutionPhase(TestCaseExecutor.java:503) at com.kms.katalon.core.main.TestCaseExecutor.accessMainPhase(TestCaseExecutor.java:495) at com.kms.katalon.core.main.TestCaseExecutor.execute(TestCaseExecutor.java:359) at com.kms.katalon.core.co | N23: H-10
A24: 326 | B24: Test HU1-1 - Verificar que un cambio de estado en la fuente se refleje automáticamente | C24: 39 - HU1-Actualizar automáticamente los estados de los envíos | D24: Eider Santiago Sánchez Lopera | E24: Manual | H24: Pendiente manual | M24: Requiere cambiar datos en la fuente y esperar el ETL
A25: 327 | B25: Test HU1-2 - Verificar el manejo de un estado no válido recibido desde la fuente | C25: 39 - HU1-Actualizar automáticamente los estados de los envíos | D25: Eider Santiago Sánchez Lopera | E25: Manual | H25: Pendiente manual | M25: Requiere cambiar datos en la fuente y esperar el ETL
A26: 328 | B26: Test HU1-5 - Verificar que el sistema rechace entradas con scripts o código malicioso | C26: 209 - HU1: Proteger la aplicación contra ataques | D26: Alejandro José Acosta Fernández | E26: Automatizado | F26: TS_P1_RutaCritica | G26: Test Cases/P1/HU209_ProteccionAtaques/TC328_RechazoEntradasMaliciosas | H26: Pasó | I26: 35.5 | J26: 2026-10-18 21:36:55 | K26: Katalon (TS_P1_RutaCritica)
A27: 329 | B27: Test HU1-1 - Verificar que una notificación marcada como leída persista y disminuya el contador | C27: 43 - HU1-Recibir notificaciones cuando el estado de mi envío cambie | D27: Alejandro José Acosta Fernández | E27: Manual | H27: Pendiente manual | M27: Notificaciones: confirmar si el front ya usa backend real | N27: H-08
A28: 330 | B28: Test HU3-1 - Verificar el reintento automático de una notificación tras un fallo temporal | C28: 45 - HU3-Reintentar el envío de notificaciones fallidas | D28: Alejandro José Acosta Fernández | E28: Manual | H28: Pendiente manual | M28: Requiere simular la caída del canal de envío | N28: H-08
A29: 331 | B29: Test HU3-2 - Verificar que se respete el número máximo de reintentos de una notificación | C29: 45 - HU3-Reintentar el envío de notificaciones fallidas | D29: Alejandro José Acosta Fernández | E29: Manual | H29: Pendiente manual | M29: Requiere simular la caída del canal de envío | N29: H-08
A30: 332 | B30: Test HU3-3 - Verificar la coherencia de los estados de una notificación durante los reintentos | C30: 45 - HU3-Reintentar el envío de notificaciones fallidas | D30: Alejandro José Acosta Fernández | E30: Manual | H30: Pendiente manual | M30: Requiere simular la caída del canal de envío | N30: H-08
A31: 333 | B31: Test HU1-2 - Verificar que el cliente reciba en tiempo real la notificación del cambio de estado de su envío | C31: 43 - HU1-Recibir notificaciones cuando el estado de mi envío cambie | D31: Alejandro José Acosta Fernández | E31: Manual | H31: Pendiente manual | M31: Requiere disparar eventos en el backend (SignalR/Kafka) | N31: H-08
A32: 335 | B32: Test HU2-1 - Verificar que solo los eventos habilitados generen notificaciones automáticas | C32: 44 - HU2-Enviar notificaciones automáticas basadas en eventos del sistema | D32: Alejandro José Acosta Fernández | E32: Manual | H32: Pendiente manual | M32: Requiere disparar eventos en el backend (Kafka/Outbox) | N32: H-08
A33: 340 | B33: Test HU11-1 - Verificar que una guía muestre la misma información en todas las pantallas | C33: 37 - HU10-Consolidar la información de los envíos en una única fuente centralizada 38 - HU11-Consultar información centralizada de mis envíos 39 - HU1-Actualizar automáticamente los estados de los envíos | D33: Alejandro José Acosta Fernández | E33: Automatizado | F33: TS_Lote2_Automaticos | G33: Test Cases/Lote2/CentralizacionFrontend/TC340_MismaInformacionEnTodasLasPantallas | H33: Falló | I33: 23.6 | J33: 2026-10-18 21:53:25 | K33: Katalon (TS_Lote2_Automaticos) | L33: Test Cases/Lote2/CentralizacionFrontend/TC340_MismaInformacionEnTodasLasPantallas FAILED. Reason: com.kms.katalon.core.exception.StepFailedException: No se cumple: La guía aparece en Mis envíos at com.kms.katalon.core.util.KeywordUtil.markFailedAndStop(KeywordUtil.java:31) at conexion360.Helpers.verificar(Helpers.groovy:314) at TC340_MismaInformacionEnTodasLasPantallas.run(TC340_MismaInformacionEnTodasLasPantallas:19) at com.kms.katalon.core.main.ScriptEngine.run(ScriptEngine.java:203) at com.kms.katalon.core.main.ScriptEngine.runScriptAsRawText(ScriptEngine.java:115) at com.kms.katalon.core.main.TestCaseExecutor.runScript(TestCaseExecutor.java:533) at com.kms.katalon.core.main.TestCaseExecutor.doExecute(TestCaseExecutor.java:524) at com.kms.katalon.core.main.TestCaseExecutor.processExecutionPhase(TestCaseExecutor.java:503) at com.kms.katalon.core.main.TestCaseExecutor.accessMainPhase(TestCaseExecutor.java:495) at com.kms.katalon.core.main.TestCaseExecutor.execute(TestCaseExe | N33: H-07, H-08, H-10
A34: 341 | B34: Test HU2-1 - Verificar que el historial muestre todos los cambios de estado en orden | C34: 32 - HU5-Visualizar el historial del envío 39 - HU1-Actualizar automáticamente los estados de los envíos 41 - HU1-Registrar cada cambio en los envíos 42 - HU2-Visualizar los cambios del envío | D34: Alejandro José Acosta Fernández | E34: Automatizado parcial | F34: (individual) | G34: Test Cases/Lote2/CentralizacionFrontend/TC341_HistorialCambiosEnOrden | H34: Falló | I34: 42.5 | J34: 2026-10-18 22:06:24 | K34: Katalon (TS_Reejecucion) | L34: Test Cases/Lote2/CentralizacionFrontend/TC341_HistorialCambiosEnOrden FAILED. Reason: com.kms.katalon.core.exception.StepFailedException: No se cumple: Existe la pestaña "Historial" en el detalle at com.kms.katalon.core.util.KeywordUtil.markFailedAndStop(KeywordUtil.java:31) at conexion360.Helpers.verificar(Helpers.groovy:323) at conexion360.Helpers.abrirPestana(Helpers.groovy:247) at TC341_HistorialCambiosEnOrden.run(TC341_HistorialCambiosEnOrden:26) at com.kms.katalon.core.main.ScriptEngine.run(ScriptEngine.java:203) at com.kms.katalon.core.main.ScriptEngine.runScriptAsRawText(ScriptEngine.java:115) at com.kms.katalon.core.main.TestCaseExecutor.runScript(TestCaseExecutor.java:533) at com.kms.katalon.core.main.TestCaseExecutor.doExecute(TestCaseExecutor.java:524) at com.kms.katalon.core.main.TestCaseExecutor.processExecutionPhase(TestCaseExecutor.java:503) at com.kms.katalon.core.main.TestCaseExecutor.accessMainPhase(TestCaseExecutor.java:495) at com.kms.katalon.core.main.T | M34: Requiere hacer antes 3 cambios de estado en BPMS | N34: H-08, H-10
A35: 342 | B35: Test HU1-3 - Verificar que el mismo cambio no genere notificaciones duplicadas | C35: 43 - HU1-Recibir notificaciones cuando el estado de mi envío cambie 45 - HU3-Reintentar el envío de notificaciones fallidas | D35: Alejandro José Acosta Fernández | E35: Manual | H35: Pendiente manual | M35: Flujo de notificaciones en backend (Kafka/SignalR)
A36: 343 | B36: Test HU10-1 - Verificar el estado mostrado cuando las fuentes no coinciden | C36: 37 - HU10-Consolidar la información de los envíos en una única fuente centralizada 39 - HU1-Actualizar automáticamente los estados de los envíos | D36: Alejandro José Acosta Fernández | E36: Manual | H36: Pendiente manual | M36: Requiere manipular las fuentes de datos / ETL
A37: 344 | B37: Test HU11-2 - Verificar que cada estado logístico se muestre con su valor real | C37: 33 - HU6-Ver detalles completos del envío por medio de iconos 38 - HU11-Consultar información centralizada de mis envíos | D37: Alejandro José Acosta Fernández | E37: Automatizado | F37: TS_Lote2_Automaticos | G37: Test Cases/Lote2/CentralizacionFrontend/TC344_EstadosLogisticosConSuValorReal | H37: Falló | I37: 16.4 | J37: 2026-10-18 21:53:25 | K37: Katalon (TS_Lote2_Automaticos) | L37: Test Cases/Lote2/CentralizacionFrontend/TC344_EstadosLogisticosConSuValorReal FAILED. Reason: com.kms.katalon.core.exception.StepFailedException: No se cumple: HBLQA0003 aparece en Mis envíos at com.kms.katalon.core.util.KeywordUtil.markFailedAndStop(KeywordUtil.java:31) at conexion360.Helpers.verificar(Helpers.groovy:314) at Script1792247532472$_run_closure1.doCall(Script1792247532472.groovy:33) at java.base/jdk.internal.reflect.DirectMethodHandleAccessor.invoke(DirectMethodHandleAccessor.java:103) at TC344_EstadosLogisticosConSuValorReal.run(TC344_EstadosLogisticosConSuValorReal:29) at com.kms.katalon.core.main.ScriptEngine.run(ScriptEngine.java:203) at com.kms.katalon.core.main.ScriptEngine.runScriptAsRawText(ScriptEngine.java:115) at com.kms.katalon.core.main.TestCaseExecutor.runScript(TestCaseExecutor.java:533) at com.kms.katalon.core.main.TestCaseExecutor.doExecute(TestCaseExecutor.java:524) at com.kms.katalon.core.main.TestCaseExecutor.processExecutionPhase(TestCaseExe | N37: H-08, H-10
A38: 345 | B38: Test HU10-2 - Verificar que una guía nueva en las 5 fuentes se consolide en un solo envío | C38: 37 - HU10-Consolidar la información de los envíos en una única fuente centralizada 38 - HU11-Consultar información centralizada de mis envíos | D38: Alejandro José Acosta Fernández | E38: Manual | H38: Pendiente manual | M38: Requiere manipular las fuentes de datos / ETL
A39: 346 | B39: Test HU10-3 - Verificar el manejo de una guía con cliente distinto entre fuentes | C39: 37 - HU10-Consolidar la información de los envíos en una única fuente centralizada 126 - HU3: Visualización envios | D39: Alejandro José Acosta Fernández | E39: Manual | H39: Pendiente manual | M39: Requiere manipular las fuentes de datos / ETL
A40: 347 | B40: Test HU2-1 - Verificar el flujo completo desde una guía nueva hasta la notificación | C40: 37 - HU10-Consolidar la información de los envíos en una única fuente centralizada 40 - HU2-Integrar múltiples fuentes de datos 43 - HU1-Recibir notificaciones cuando el estado de mi envío cambie 126 - HU3: Visualización envios | D40: Alejandro José Acosta Fernández | E40: Manual | H40: Pendiente manual | M40: Flujo de notificaciones en backend (Kafka/SignalR)
...

Sheet HU_Caso
A1: HU | B1: Título HU | C1: ID caso | D1: Resultado
A2: 34 | B2: HU7-Buscar un envío por número de guía | C2: 304 | D2: =INDEX(Detalle!$H$2:$H$78,MATCH(C2,Detalle!$A$2:$A$78,0))
A3: 34 | B3: HU7-Buscar un envío por número de guía | C3: 305 | D3: =INDEX(Detalle!$H$2:$H$78,MATCH(C3,Detalle!$A$2:$A$78,0))
A4: 34 | B4: HU7-Buscar un envío por número de guía | C4: 306 | D4: =INDEX(Detalle!$H$2:$H$78,MATCH(C4,Detalle!$A$2:$A$78,0))
A5: 28 | B5: HU1-Lista de mis envíos activos | C5: 307 | D5: =INDEX(Detalle!$H$2:$H$78,MATCH(C5,Detalle!$A$2:$A$78,0))
A6: 28 | B6: HU1-Lista de mis envíos activos | C6: 308 | D6: =INDEX(Detalle!$H$2:$H$78,MATCH(C6,Detalle!$A$2:$A$78,0))
A7: 121 | B7: HU2: Inicio de sesión | C7: 309 | D7: =INDEX(Detalle!$H$2:$H$78,MATCH(C7,Detalle!$A$2:$A$78,0))
A8: 121 | B8: HU2: Inicio de sesión | C8: 310 | D8: =INDEX(Detalle!$H$2:$H$78,MATCH(C8,Detalle!$A$2:$A$78,0))
A9: 121 | B9: HU2: Inicio de sesión | C9: 311 | D9: =INDEX(Detalle!$H$2:$H$78,MATCH(C9,Detalle!$A$2:$A$78,0))
A10: 121 | B10: HU2: Inicio de sesión | C10: 312 | D10: =INDEX(Detalle!$H$2:$H$78,MATCH(C10,Detalle!$A$2:$A$78,0))
A11: 214 | B11: HU6: Bloquear acceso tras 3 intentos fallidos | C11: 313 | D11: =INDEX(Detalle!$H$2:$H$78,MATCH(C11,Detalle!$A$2:$A$78,0))
A12: 214 | B12: HU6: Bloquear acceso tras 3 intentos fallidos | C12: 314 | D12: =INDEX(Detalle!$H$2:$H$78,MATCH(C12,Detalle!$A$2:$A$78,0))
A13: 214 | B13: HU6: Bloquear acceso tras 3 intentos fallidos | C13: 315 | D13: =INDEX(Detalle!$H$2:$H$78,MATCH(C13,Detalle!$A$2:$A$78,0))
... A113: 44 | B113: HU2-Enviar notificaciones automáticas basadas en eventos del sistema | C113: 385 | D113: =INDEX(Detalle!$H$2:$H$78,MATCH(C113,Detalle!$A$2:$A$78,0))

Sheet Ejecuciones
A1: Fecha | B1: Suite | C1: ID Azure | D1: Caso Katalon | E1: Resultado | F1: Duración (s) | G1: Mensaje | H1: Reporte
A2: 2026-10-18 22:06:24 | B2: TS_Reejecucion | C2: 350 | D2: Test Cases/Lote2/Notificaciones/TC350_NotificacionAbreDetalleCorrecto | E2: Falló | F2: 43.5 | G2: Test Cases/Lote2/Notificaciones/TC350_NotificacionAbreDetalleCorrecto FAILED. Reason: com.kms.katalon.core.exception.StepFailedException: Unable to click on object 'xpath_4b98f5e' at com.kms.katalon.core.webui.keyword.internal.WebUIKeywordMain.stepFailed(WebUIKeywordMain.groovy:177) at com.kms.katalon.core.webui.keyword.internal.WebUIKeywordMain.runKeyword(WebUIKeywordMain.groovy:49) at com.kms.katalon.core.webui.keyword.internal.WebUIKeywordMain.runKeywordUntilTimeout(WebUIKeywordMain.groovy:133) at com.kms.katalon.core.webui.keyword.builtin.ClickKeyword.click(ClickKeyword.groovy:72) at com.kms.katalon.core.webui.keyword.builtin.ClickKeyword.execute(ClickKeyword.groovy:38) at com.kms.katalon.core.keyword.internal.KeywordExecutor.executeKeywordForPlatform(KeywordExecutor.groovy:106) at com.kms.katalon.core.webui.keyword.WebUiBuiltInKeywords.click(WebUiBuiltInKeywords.groovy:722) at TC350_NotificacionAbreDetalleCorrecto.run(TC350_NotificacionAbreDetalleCorrecto:21) at com.kms.k | H2: Reports/20261018_170614/TS_Reejecucion/20261018_170614/JUnit_Report.xml
A3: 2026-10-18 22:06:24 | B3: TS_Reejecucion | C3: 341 | D3: Test Cases/Lote2/CentralizacionFrontend/TC341_HistorialCambiosEnOrden | E3: Falló | F3: 42.5 | G3: Test Cases/Lote2/CentralizacionFrontend/TC341_HistorialCambiosEnOrden FAILED. Reason: com.kms.katalon.core.exception.StepFailedException: No se cumple: Existe la pestaña "Historial" en el detalle at com.kms.katalon.core.util.KeywordUtil.markFailedAndStop(KeywordUtil.java:31) at conexion360.Helpers.verificar(Helpers.groovy:323) at conexion360.Helpers.abrirPestana(Helpers.groovy:247) at TC341_HistorialCambiosEnOrden.run(TC341_HistorialCambiosEnOrden:26) at com.kms.katalon.core.main.ScriptEngine.run(ScriptEngine.java:203) at com.kms.katalon.core.main.ScriptEngine.runScriptAsRawText(ScriptEngine.java:115) at com.kms.katalon.core.main.TestCaseExecutor.runScript(TestCaseExecutor.java:533) at com.kms.katalon.core.main.TestCaseExecutor.doExecute(TestCaseExecutor.java:524) at com.kms.katalon.core.main.TestCaseExecutor.processExecutionPhase(TestCaseExecutor.java:503) at com.kms.katalon.core.main.TestCaseExecutor.accessMainPhase(TestCaseExecutor.java:495) at com.kms.katalon.core.main.T | H3: Reports/20261018_170614/TS_Reejecucion/20261018_170614/JUnit_Report.xml
A4: 2026-10-18 22:06:24 | B4: TS_Reejecucion | C4: 373 | D4: Test Cases/Lote2/SeguridadAcceso/TC373_ServiciosExigenAutenticacion | E4: Falló | F4: 7.3 | G4: Test Cases/Lote2/SeguridadAcceso/TC373_ServiciosExigenAutenticacion FAILED. Reason: com.kms.katalon.core.exception.StepFailedException: No se cumple: /myshipments/allshipments?idClient=3127584817&page=1&size=10 sin token responde 503 (esperado 401) at com.kms.katalon.core.util.KeywordUtil.markFailedAndStop(KeywordUtil.java:31) at conexion360.Helpers.verificar(Helpers.groovy:323) at Script1792248059895$_run_closure1.doCall(Script1792248059895.groovy:29) at java.base/jdk.internal.reflect.DirectMethodHandleAccessor.invoke(DirectMethodHandleAccessor.java:103) at TC373_ServiciosExigenAutenticacion.run(TC373_ServiciosExigenAutenticacion:27) at com.kms.katalon.core.main.ScriptEngine.run(ScriptEngine.java:203) at com.kms.katalon.core.main.ScriptEngine.runScriptAsRawText(ScriptEngine.java:115) at com.kms.katalon.core.main.TestCaseExecutor.runScript(TestCaseExecutor.java:533) at com.kms.katalon.core.main.TestCaseExecutor.doExecute(TestCaseExecutor.java:524) at com.kms.katalon.core.main | H4: Reports/20261018_170614/TS_Reejecucion/20261018_170614/JUnit_Report.xml
A5: 2026-10-18 22:06:24 | B5: TS_Reejecucion | C5: 365 | D5: Test Cases/Lote2/SeguridadAcceso/TC365_ApiCambioIdClientNoMuestraOtroCliente | E5: Pasó | F5: 16.8 | H5: Reports/20261018_170614/TS_Reejecucion/20261018_170614/JUnit_Report.xml
A6: 2026-10-18 22:06:24 | B6: TS_Reejecucion | C6: 357 | D6: Test Cases/Lote2/SeguridadAcceso/TC357_ApiIdQueryClientDeOtroCliente | E6: Pasó | F6: 12.8 | H6: Reports/20261018_170614/TS_Reejecucion/20261018_170614/JUnit_Report.xml
A7: 2026-10-18 22:06:24 | B7: TS_Reejecucion | C7: 351 | D7: Test Cases/Lote2/SeguridadAcceso/TC351_ClienteSinAccesoAdministracion | E7: Falló | F7: 19.2 | G7: Test Cases/Lote2/SeguridadAcceso/TC351_ClienteSinAccesoAdministracion FAILED. Reason: com.kms.katalon.core.exception.StepFailedException: No se cumple: GET /settings/listusers responde 503 (esperado 403) at com.kms.katalon.core.util.KeywordUtil.markFailedAndStop(KeywordUtil.java:31) at conexion360.Helpers.verificar(Helpers.groovy:323) at TC351_ClienteSinAccesoAdministracion.run(TC351_ClienteSinAccesoAdministracion:26) at com.kms.katalon.core.main.ScriptEngine.run(ScriptEngine.java:203) at com.kms.katalon.core.main.ScriptEngine.runScriptAsRawText(ScriptEngine.java:115) at com.kms.katalon.core.main.TestCaseExecutor.runScript(TestCaseExecutor.java:533) at com.kms.katalon.core.main.TestCaseExecutor.doExecute(TestCaseExecutor.java:524) at com.kms.katalon.core.main.TestCaseExecutor.processExecutionPhase(TestCaseExecutor.java:503) at com.kms.katalon.core.main.TestCaseExecutor.accessMainPhase(TestCaseExecutor.java:495) at com.kms.katalon.core.main.TestCaseExecutor.execute(TestCaseExe | H7: Reports/20261018_170614/TS_Reejecucion/20261018_170614/JUnit_Report.xml
A8: 2026-10-18 22:06:24 | B8: TS_Reejecucion | C8: 324 | D8: Test Cases/P1/HU30_DetalleEnvio/TC324_DetalleEnvioPropio | E8: Falló | F8: 31.8 | G8: Test Cases/P1/HU30_DetalleEnvio/TC324_DetalleEnvioPropio FAILED. Reason: com.kms.katalon.core.exception.StepFailedException: Unable to click on object 'css_2950d483' at com.kms.katalon.core.webui.keyword.internal.WebUIKeywordMain.stepFailed(WebUIKeywordMain.groovy:177) at com.kms.katalon.core.webui.keyword.internal.WebUIKeywordMain.runKeyword(WebUIKeywordMain.groovy:49) at com.kms.katalon.core.webui.keyword.internal.WebUIKeywordMain.runKeywordUntilTimeout(WebUIKeywordMain.groovy:133) at com.kms.katalon.core.webui.keyword.builtin.ClickKeyword.click(ClickKeyword.groovy:72) at com.kms.katalon.core.webui.keyword.builtin.ClickKeyword.execute(ClickKeyword.groovy:38) at com.kms.katalon.core.keyword.internal.KeywordExecutor.executeKeywordForPlatform(KeywordExecutor.groovy:106) at com.kms.katalon.core.webui.keyword.WebUiBuiltInKeywords.click(WebUiBuiltInKeywords.groovy:722) at TC324_DetalleEnvioPropio.run(TC324_DetalleEnvioPropio:20) at com.kms.katalon.core.main.ScriptEngine.run(Script | H8: Reports/20261018_170614/TS_Reejecucion/20261018_170614/JUnit_Report.xml
A9: 2026-10-18 22:06:24 | B9: TS_Reejecucion | C9: 318 | D9: Test Cases/P1/HU126_OwnershipEnvios/TC318_ApiRechazaEnvioAjeno | E9: Falló | F9: 19.7 | G9: Test Cases/P1/HU126_OwnershipEnvios/TC318_ApiRechazaEnvioAjeno FAILED. Reason: com.kms.katalon.core.exception.StepFailedException: No se cumple: El token y el endpoint funcionan con el envío propio at com.kms.katalon.core.util.KeywordUtil.markFailedAndStop(KeywordUtil.java:31) at conexion360.Helpers.verificar(Helpers.groovy:323) at TC318_ApiRechazaEnvioAjeno.run(TC318_ApiRechazaEnvioAjeno:24) at com.kms.katalon.core.main.ScriptEngine.run(ScriptEngine.java:203) at com.kms.katalon.core.main.ScriptEngine.runScriptAsRawText(ScriptEngine.java:115) at com.kms.katalon.core.main.TestCaseExecutor.runScript(TestCaseExecutor.java:533) at com.kms.katalon.core.main.TestCaseExecutor.doExecute(TestCaseExecutor.java:524) at com.kms.katalon.core.main.TestCaseExecutor.processExecutionPhase(TestCaseExecutor.java:503) at com.kms.katalon.core.main.TestCaseExecutor.accessMainPhase(TestCaseExecutor.java:495) at com.kms.katalon.core.main.TestCaseExecutor.execute(TestCaseExecutor.java:359) at com.km | H9: Reports/20261018_170614/TS_Reejecucion/20261018_170614/JUnit_Report.xml
A10: 2026-10-18 21:53:25 | B10: TS_Lote2_Automaticos | C10: 374 | D10: Test Cases/Lote2/SeguridadAcceso/TC374_ClienteNoVeRankingEnReportes | E10: Falló | F10: 70 | G10: Test Cases/Lote2/SeguridadAcceso/TC374_ClienteNoVeRankingEnReportes FAILED. Reason: com.kms.katalon.core.exception.StepFailedException: No apareció el texto: Reportes at com.kms.katalon.core.util.KeywordUtil.markFailedAndStop(KeywordUtil.java:31) at conexion360.Helpers.esperarTexto(Helpers.groovy:108) at conexion360.Helpers.esperarTexto(Helpers.groovy) at TC374_ClienteNoVeRankingEnReportes.run(TC374_ClienteNoVeRankingEnReportes:27) at com.kms.katalon.core.main.ScriptEngine.run(ScriptEngine.java:203) at com.kms.katalon.core.main.ScriptEngine.runScriptAsRawText(ScriptEngine.java:115) at com.kms.katalon.core.main.TestCaseExecutor.runScript(TestCaseExecutor.java:533) at com.kms.katalon.core.main.TestCaseExecutor.doExecute(TestCaseExecutor.java:524) at com.kms.katalon.core.main.TestCaseExecutor.processExecutionPhase(TestCaseExecutor.java:503) at com.kms.katalon.core.main.TestCaseExecutor.accessMainPhase(TestCaseExecutor.java:495) at com.kms.katalon.core.main.TestCaseExecutor.exec | H10: Reports/20261018_165316/TS_Lote2_Automaticos/20261018_165316/JUnit_Report.xml
A11: 2026-10-18 21:53:25 | B11: TS_Lote2_Automaticos | C11: 373 | D11: Test Cases/Lote2/SeguridadAcceso/TC373_ServiciosExigenAutenticacion | E11: Error | F11: 6 | G11: Test Cases/Lote2/SeguridadAcceso/TC373_ServiciosExigenAutenticacion FAILED. Reason: groovy.lang.MissingMethodException: No signature of method: static com.kms.katalon.core.webui.keyword.WebUiBuiltInKeywords.executeAsyncJavaScript() is applicable for argument types: (String, ArrayList, com.kms.katalon.core.model.FailureHandling) values: [ const done = arguments[arguments.length - 1]; const [url, metodo, cuerpo, conToken] = arguments; const headers = {}; if (conToken) { const key = Object.keys(localStorage).find(k => k.startsWith('@@auth0spajs@@') && !k.includes('@@user@@')); headers.Authorization = 'Bearer ' + (key ? JSON.parse(localStorage.getItem(key)).body.access_token : ''); } if (cuerpo) headers['Content-Type'] = 'application/json'; fetch(url, { method: metodo, headers: headers, body: cuerpo || undefined }) .then(r => r.text().then(t => done({ status: r.status, body: t }))) .catch(e => done({ status: -1, body: String(e) })); , ...] at conexio | H11: Reports/20261018_165316/TS_Lote2_Automaticos/20261018_165316/JUnit_Report.xml
